TypeError: load_dataset() got an unexpected keyword argument 'test_with_fake_data'

Environment info
Operating System: ubuntu 14.04 and Mac OSX
Pip install: 0.9.0
In 'tensorflow/tensorflow/examples/skflow/' folder, when run 'text_classification*.py',
the code
'''
dbpedia = learn.datasets.load_dataset(
'dbpedia', test_with_fake_data=FLAGS.test_with_fake_data)
'''
cause a bug
'''
TypeError: load_dataset() got an unexpected keyword argument 'test_with_fake_data'
'''
It is because that if user install tensorflow by pip, the definition of 'load_dataset()' in 'tensorflow/tensorflow/contrib/learn/python/learn/datasets/init.py' is
'def load_dataset(name):',
but in current git version, the definition of 'load_dataset()' is
'def load_dataset(name, size='small', test_with_fake_data=False):'.