ResourceExhaustedError on GPU

Environment info
Operating System: Ubuntu 16.04
Installed version of CUDA and cuDNN: CUDA 8.0, cuDNN 5
(please attach the output of ls -l /path/to/cuda/lib/libcud*):
/usr/local/cuda/lib64/libcudadevrt.a
/usr/local/cuda/lib64/libcudart.so
/usr/local/cuda/lib64/libcudart.so.8.0
/usr/local/cuda/lib64/libcudart.so.8.0.27
/usr/local/cuda/lib64/libcudart_static.a
/usr/local/cuda/lib64/libcudnn.so
/usr/local/cuda/lib64/libcudnn.so.5
/usr/local/cuda/lib64/libcudnn.so.5.0.5
If installed from sources, provide the commit hash:
2cbb9b5
Hi All,
I am able to run the following code on CPU, but when on GPU, I got a ResourceExhaustedError, My GPU is an GTX1080 one, which has 8G memeory.
import tensorflow as tf
import numpy as np

sess = tf.Session()

inputs = tf.placeholder(tf.float32, shape=(30,224,224,512))
with tf.device('/gpu:0') as d:
    kernel = tf.Variable(tf.truncated_normal([9,9,512,36], dtype=tf.float32,stddev=1e-1), name='weights')
    conv = tf.nn.conv2d(inputs, kernel, [1, 1, 1, 1], padding='SAME')

inputs_arr = np.random.random((30,224,224,512)).astype(np.float32)
sess.run(tf.initialize_variables([kernel]))
cc = sess.run(conv, feed_dict={inputs: inputs_arr})

Error message:
---------------------------------------------------------------------------
ResourceExhaustedError                    Traceback (most recent call last)
/home/xlws/anaconda3/lib/python3.5/site-packages/tensorflow/python/client/session.py in _do_call(self, fn, *args)
    971     try:
--> 972       return fn(*args)
    973     except errors.OpError as e:

/home/xlws/anaconda3/lib/python3.5/site-packages/tensorflow/python/client/session.py in _run_fn(session, feed_dict, fetch_list, target_list, options, run_metadata)
    953                                  feed_dict, fetch_list, target_list,
--> 954                                  status, run_metadata)
    955 

/home/xlws/anaconda3/lib/python3.5/contextlib.py in __exit__(self, type, value, traceback)
     65             try:
---> 66                 next(self.gen)
     67             except StopIteration:

/home/xlws/anaconda3/lib/python3.5/site-packages/tensorflow/python/framework/errors.py in raise_exception_on_not_ok_status()
    462           compat.as_text(pywrap_tensorflow.TF_Message(status)),
--> 463           pywrap_tensorflow.TF_GetCode(status))
    464   finally:

ResourceExhaustedError: OOM when allocating tensor with shape[30,36,224,224]
     [[Node: Conv2D = Conv2D[T=DT_FLOAT, data_format="NHWC", padding="SAME", strides=[1, 1, 1, 1], use_cudnn_on_gpu=true, _device="/job:localhost/replica:0/task:0/gpu:0"](_recv_Placeholder_0/_1, weights/read)]]
     [[Node: Conv2D/_3 = _Recv[client_terminated=false, recv_device="/job:localhost/replica:0/task:0/cpu:0", send_device="/job:localhost/replica:0/task:0/gpu:0", send_device_incarnation=1, tensor_name="edge_4_Conv2D", tensor_type=DT_FLOAT, _device="/job:localhost/replica:0/task:0/cpu:0"]()]]

During handling of the above exception, another exception occurred:

ResourceExhaustedError                    Traceback (most recent call last)
<ipython-input-1-92fd065a1eed> in <module>()
     12 inputs_arr = np.random.random((30,224,224,512)).astype(np.float32)
     13 sess.run(tf.initialize_variables([kernel]))
---> 14 cc = sess.run(conv, feed_dict={inputs: inputs_arr})

/home/xlws/anaconda3/lib/python3.5/site-packages/tensorflow/python/client/session.py in run(self, fetches, feed_dict, options, run_metadata)
    715     try:
    716       result = self._run(None, fetches, feed_dict, options_ptr,
--> 717                          run_metadata_ptr)
    718       if run_metadata:
    719         proto_data = tf_session.TF_GetBuffer(run_metadata_ptr)

/home/xlws/anaconda3/lib/python3.5/site-packages/tensorflow/python/client/session.py in _run(self, handle, fetches, feed_dict, options, run_metadata)
    913     if final_fetches or final_targets:
    914       results = self._do_run(handle, final_targets, final_fetches,
--> 915                              feed_dict_string, options, run_metadata)
    916     else:
    917       results = []

/home/xlws/anaconda3/lib/python3.5/site-packages/tensorflow/python/client/session.py in _do_run(self, handle, target_list, fetch_list, feed_dict, options, run_metadata)
    963     if handle is None:
    964       return self._do_call(_run_fn, self._session, feed_dict, fetch_list,
--> 965                            target_list, options, run_metadata)
    966     else:
    967       return self._do_call(_prun_fn, self._session, handle, feed_dict,

/home/xlws/anaconda3/lib/python3.5/site-packages/tensorflow/python/client/session.py in _do_call(self, fn, *args)
    983         except KeyError:
    984           pass
--> 985       raise type(e)(node_def, op, message)
    986 
    987   def _extend_graph(self):

ResourceExhaustedError: OOM when allocating tensor with shape[30,36,224,224]
     [[Node: Conv2D = Conv2D[T=DT_FLOAT, data_format="NHWC", padding="SAME", strides=[1, 1, 1, 1], use_cudnn_on_gpu=true, _device="/job:localhost/replica:0/task:0/gpu:0"](_recv_Placeholder_0/_1, weights/read)]]
     [[Node: Conv2D/_3 = _Recv[client_terminated=false, recv_device="/job:localhost/replica:0/task:0/cpu:0", send_device="/job:localhost/replica:0/task:0/gpu:0", send_device_incarnation=1, tensor_name="edge_4_Conv2D", tensor_type=DT_FLOAT, _device="/job:localhost/replica:0/task:0/cpu:0"]()]]

Caused by op 'Conv2D', defined at:
  File "/home/xlws/anaconda3/lib/python3.5/runpy.py", line 184, in _run_module_as_main
    "__main__", mod_spec)
  File "/home/xlws/anaconda3/lib/python3.5/runpy.py", line 85, in _run_code
    exec(code, run_globals)
  File "/home/xlws/anaconda3/lib/python3.5/site-packages/ipykernel/__main__.py", line 3, in <module>
    app.launch_new_instance()
  File "/home/xlws/anaconda3/lib/python3.5/site-packages/traitlets/config/application.py", line 596, in launch_instance
    app.start()
  File "/home/xlws/anaconda3/lib/python3.5/site-packages/ipykernel/kernelapp.py", line 442, in start
    ioloop.IOLoop.instance().start()
  File "/home/xlws/anaconda3/lib/python3.5/site-packages/zmq/eventloop/ioloop.py", line 162, in start
    super(ZMQIOLoop, self).start()
  File "/home/xlws/anaconda3/lib/python3.5/site-packages/tornado/ioloop.py", line 883, in start
    handler_func(fd_obj, events)
  File "/home/xlws/anaconda3/lib/python3.5/site-packages/tornado/stack_context.py", line 275, in null_wrapper
    return fn(*args, **kwargs)
  File "/home/xlws/anaconda3/lib/python3.5/site-packages/zmq/eventloop/zmqstream.py", line 440, in _handle_events
    self._handle_recv()
  File "/home/xlws/anaconda3/lib/python3.5/site-packages/zmq/eventloop/zmqstream.py", line 472, in _handle_recv
    self._run_callback(callback, msg)
  File "/home/xlws/anaconda3/lib/python3.5/site-packages/zmq/eventloop/zmqstream.py", line 414, in _run_callback
    callback(*args, **kwargs)
  File "/home/xlws/anaconda3/lib/python3.5/site-packages/tornado/stack_context.py", line 275, in null_wrapper
    return fn(*args, **kwargs)
  File "/home/xlws/anaconda3/lib/python3.5/site-packages/ipykernel/kernelbase.py", line 276, in dispatcher
    return self.dispatch_shell(stream, msg)
  File "/home/xlws/anaconda3/lib/python3.5/site-packages/ipykernel/kernelbase.py", line 228, in dispatch_shell
    handler(stream, idents, msg)
  File "/home/xlws/anaconda3/lib/python3.5/site-packages/ipykernel/kernelbase.py", line 391, in execute_request
    user_expressions, allow_stdin)
  File "/home/xlws/anaconda3/lib/python3.5/site-packages/ipykernel/ipkernel.py", line 199, in do_execute
    shell.run_cell(code, store_history=store_history, silent=silent)
  File "/home/xlws/anaconda3/lib/python3.5/site-packages/IPython/core/interactiveshell.py", line 2723, in run_cell
    interactivity=interactivity, compiler=compiler, result=result)
  File "/home/xlws/anaconda3/lib/python3.5/site-packages/IPython/core/interactiveshell.py", line 2825, in run_ast_nodes
    if self.run_code(code, result):
  File "/home/xlws/anaconda3/lib/python3.5/site-packages/IPython/core/interactiveshell.py", line 2885, in run_code
    exec(code_obj, self.user_global_ns, self.user_ns)
  File "<ipython-input-1-92fd065a1eed>", line 10, in <module>
    conv = tf.nn.conv2d(inputs, kernel, [1, 1, 1, 1], padding='SAME')
  File "/home/xlws/anaconda3/lib/python3.5/site-packages/tensorflow/python/ops/gen_nn_ops.py", line 394, in conv2d
    data_format=data_format, name=name)
  File "/home/xlws/anaconda3/lib/python3.5/site-packages/tensorflow/python/framework/op_def_library.py", line 748, in apply_op
    op_def=op_def)
  File "/home/xlws/anaconda3/lib/python3.5/site-packages/tensorflow/python/framework/ops.py", line 2403, in create_op
    original_op=self._default_original_op, op_def=op_def)
  File "/home/xlws/anaconda3/lib/python3.5/site-packages/tensorflow/python/framework/ops.py", line 1305, in __init__
    self._traceback = _extract_stack()

ResourceExhaustedError (see above for traceback): OOM when allocating tensor with shape[30,36,224,224]
     [[Node: Conv2D = Conv2D[T=DT_FLOAT, data_format="NHWC", padding="SAME", strides=[1, 1, 1, 1], use_cudnn_on_gpu=true, _device="/job:localhost/replica:0/task:0/gpu:0"](_recv_Placeholder_0/_1, weights/read)]]
     [[Node: Conv2D/_3 = _Recv[client_terminated=false, recv_device="/job:localhost/replica:0/task:0/cpu:0", send_device="/job:localhost/replica:0/task:0/gpu:0", send_device_incarnation=1, tensor_name="edge_4_Conv2D", tensor_type=DT_FLOAT, _device="/job:localhost/replica:0/task:0/cpu:0"]()]]