Failed to load the native TensorFlow runtime : error while importing tensorflow

I built TensorFlow from source on my Ubuntu 17.04 32bit
I got this message while importing tensorflow
palash@ash:~$ python
Python 3.6.0 |Anaconda 4.3.1 (32-bit)| (default, Dec 23 2016, 12:22:10)
[GCC 4.4.7 20120313 (Red Hat 4.4.7-1)] on linux
Type "help", "copyright", "credits" or "license" for more information.



import tensorflow
Traceback (most recent call last):
File "/home/palash/anaconda3/lib/python3.6/site-packages/tensorflow/python/init.py", line 61, in 
from tensorflow.python import pywrap_tensorflow
File "/home/palash/anaconda3/lib/python3.6/site-packages/tensorflow/python/pywrap_tensorflow.py", line 28, in 
_pywrap_tensorflow = swig_import_helper()
File "/home/palash/anaconda3/lib/python3.6/site-packages/tensorflow/python/pywrap_tensorflow.py", line 24, in swig_import_helper
_mod = imp.load_module('_pywrap_tensorflow', fp, pathname, description)
File "/home/palash/anaconda3/lib/python3.6/imp.py", line 242, in load_module
return load_dynamic(name, filename, file)
File "/home/palash/anaconda3/lib/python3.6/imp.py", line 342, in load_dynamic
return _load(spec)
ImportError: /home/palash/anaconda3/bin/../lib/libstdc++.so.6: version `GLIBCXX_3.4.21' not found (required by /home/palash/anaconda3/lib/python3.6/site-packages/tensorflow/python/_pywrap_tensorflow.so)



During handling of the above exception, another exception occurred:
Traceback (most recent call last):
File "", line 1, in 
File "/home/palash/anaconda3/lib/python3.6/site-packages/tensorflow/init.py", line 24, in 
from tensorflow.python import *
File "/home/palash/anaconda3/lib/python3.6/site-packages/tensorflow/python/init.py", line 72, in 
raise ImportError(msg)
ImportError: Traceback (most recent call last):
File "/home/palash/anaconda3/lib/python3.6/site-packages/tensorflow/python/init.py", line 61, in 
from tensorflow.python import pywrap_tensorflow
File "/home/palash/anaconda3/lib/python3.6/site-packages/tensorflow/python/pywrap_tensorflow.py", line 28, in 
_pywrap_tensorflow = swig_import_helper()
File "/home/palash/anaconda3/lib/python3.6/site-packages/tensorflow/python/pywrap_tensorflow.py", line 24, in swig_import_helper
_mod = imp.load_module('_pywrap_tensorflow', fp, pathname, description)
File "/home/palash/anaconda3/lib/python3.6/imp.py", line 242, in load_module
return load_dynamic(name, filename, file)
File "/home/palash/anaconda3/lib/python3.6/imp.py", line 342, in load_dynamic
return _load(spec)
ImportError: /home/palash/anaconda3/bin/../lib/libstdc++.so.6: version `GLIBCXX_3.4.21' not found (required by /home/palash/anaconda3/lib/python3.6/site-packages/tensorflow/python/_pywrap_tensorflow.so)
Failed to load the native TensorFlow runtime.
See https://github.com/tensorflow/tensorflow/blob/master/tensorflow/g3doc/get_started/os_setup.md#import_error
for some common reasons and solutions.  Include the entire stack trace
above this error message when asking for help.






my bazel info:
palash@ash:~$ bazel version
Build label: 0.4.5- (@non-git)
Build target: bazel-out/local-opt/bin/src/main/java/com/google/devtools/build/lib/bazel/BazelServer_deploy.jar
Build time: Fri May 19 01:31:26 2017 (1495157486)
Build timestamp: 1495157486
Build timestamp as int: 1495157486
my TensorFlow version : 1.0.1